Workbook

Sheet Dashboard
B1: PORTFOLIO FIDELITY 2024
B2: OVERVIEW | F2: PERFORMANCE | J2: DIVIDEND STATS | N2: DIVIDEND INCOME EXPECTED | S2: Total Holdings: | W2: Notes
B3: Cost Basis | D3: Market Value | F3: Market Return ($) | H3: Market Return (%) | J3: Dividend Yield | L3: Yield On Cost | N3: Annual | P3: Monthly | S3: =Positions!A32 -> 17 | W3: Investment Strategy:
B4: =Positions!AA32 -> 34841.691 | D4: =Positions!AB32 -> 40306.351 | F4: =Positions!O32 -> 5464.6604 | H4: =Positions!Q32 -> 0.20328763 | J4: =Positions!X32 -> 0.021898336 | L4: =Positions!Y32 -> 0.025332927 | N4: =Positions!AC32 -> 882.64201 | P4: =(N4/12) -> 73.553501 | W4: - Focus on using capital for dividend growth companies and potential capital gains. - Increase allocation in ETFs/index funds. - Keep cash position between 10% and 15%. - Max allocation: 10% per stock and 20% per ETF. - No more than 30 holdings.
B5: Day Gain ($) | D5: Day Gain (%) | F5: Total Return ($) | H5: Total Return (%) | J5: Div. Growth Rate | L5: Div. Received | N5: Weekly | P5: Daily
B6: =Positions!K32 -> -149.30738 | D6: =Positions!J32 -> -0.0037180869 | F6: =Positions!P32 -> 6471.6504 | H6: =Positions!R32 -> 0.24074808 | J6: =Positions!Z32 -> 0.045599895 | L6: =Positions!AE32 -> 1006.99 | N6: =(N4/52) -> 16.973885 | P6: =(N4/365) -> 2.4181973 | W6: Advice to keep in mind:
B7: CASH | F7: SOLD POSITIONS | J7: ESTIMATED TAXES (2024) | N7: DIVIDEND INCOME CUMULATED | W7: - Take some profits from all positions that don't align with long-term goals by trimming or selling if: * growth type: when they fully recover or are overvalued. * value type: when they cut the dividend. - Rebalance the portfolio to align with the allocation target by adding money in specific categories and cutting some positions if they are too overexposed. - Find a sweet spot between not selling at all, no matter what, and selling if the company is overvalued, no matter what. * If the position is highly overvalued and rebalancing others cannot reduce its allocation, trimming it and taking profits could make sense. Otherwise, adding to other positions reduces the allocation of the one that is overexposed. - Don't overthink whether the business is good by waiting for the right price. Don't let stock price inform valuation opinion. Just go for it; don't miss the opportunity to enter right away or to keep increasing your position. - Don't skip your portfolio contributions; try to deposit at least a small amount every month.
B8: Available to trade | F8: Market Return ($) | J8: Dividend | L8: Sold Positions | N8: Annual | P8: Monthly
B9: =Positions!C34 -> 7960.27 | F9: ='Sold Positions'!I16 -> -95.078 | J9: ='Dividend Log'!AG4 -> 9.0456 | L9: ='Sold Positions'!M16 -> 0 | N9: ='Dividend Log'!N1 -> 886.2 | P9: =(N9/12) -> 73.85
B10: Weighting (Market Value) | F10: Total Return ($) | J10: Total | N10: Weekly | P10: Daily
B11: =Positions!C35 -> 0.19749419 | F11: ='Sold Positions'!J16 -> -88.378 | J11: =J9+L9 -> 9.0456 | N11: =(N9/52) -> 17.042308 | P11: =(N9/365) -> 2.4279452
W25: Opportunities Screening
W27: Watchlist | Y27: Portfolio
W29: =Watchlist!A2 -> AAPL | X29: =Watchlist!W2 -> Overrated | Y29: =Positions!A2 -> GOOGL | Z29: =Positions!AJ2 -> Hold
W30: =Watchlist!A3 -> V | X30: =Watchlist!W3 -> Overrated | Y30: =Positions!A3 -> MSFT | Z30: =Positions!AJ3 -> Avg. Cost
W31: =Watchlist!A4 -> PEP | X31: =Watchlist!W4 -> Overrated | Y31: =Positions!A4 -> DIS | Z31: =Positions!AJ4 -> Overcost
W32: =Watchlist!A5 -> MO | X32: =Watchlist!W5 -> Strong Buy | Y32: =Positions!A5 -> TGT | Z32: =Positions!AJ5 -> Avg. Cost
W33: =Watchlist!A6 -> ABBV | X33: =Watchlist!W6 -> Overrated | Y33: =Positions!A6 -> SBUX | Z33: =Positions!AJ6 -> Hold
W34: =Watchlist!A7 -> JNJ | X34: =Watchlist!W7 -> Overrated | Y34: =Positions!A7 -> JPM | Z34: =Positions!AJ7 -> Hold
W35: =Watchlist!A8 -> COST | X35: =Watchlist!W8 -> Overrated | Y35: =Positions!A8 -> KO | Z35: =Positions!AJ8 -> Hold
W36: =Watchlist!A9 -> TXRH | X36: =Watchlist!W9 -> Overrated | Y36: =Positions!A9 -> O | Z36: =Positions!AJ9 -> Hold
W37: =Watchlist!A10 -> CMG | X37: =Watchlist!W10 -> Overrated | Y37: =Positions!A10 -> VICI | Z37: =Positions!AJ10 -> Avg. Cost
W38: =Watchlist!A11 -> STZ | X38: =Watchlist!W11 -> Expensive | Y38: =Positions!A11 -> UNH | Z38: =Positions!AJ11 -> Overcost
W39: =Watchlist!A12 -> CMCSA | X39: =Watchlist!W12 -> Strong Buy | Y39: =Positions!A12 -> VGT | Z39: =Positions!AJ12 -> Hold
W40: =Watchlist!A13 -> CVX | X40: =Watchlist!W13 -> Buy | Y40: =Positions!A13 -> VOO | Z40: =Positions!AJ13 -> Hold
... W49: =Watchlist!A22 | X49: =Watchlist!W22 | Y49: =Positions!A22 | Z49: =Positions!AJ22
W50: =Watchlist!A23 | X50: =Watchlist!W23 | Z50: =Positions!AJ23
B52: Dividend Dashboard | S52: Performance
S55: YTD Annual Return | W55: Portfolio Projection
S56: Portfolio | V56: ='Annual Data'!F3 -> 0 | W56: Years | Y56: ='Portfolio Projections'!N3 -> 20
S58: S&P 500 | V58: ='Annual Data'!G3 -> 0.1788 | W58: Projected Value | Y58: ='Portfolio Projections'!L15 -> 1628754.8
S60: Difference | V60: =V56-V58 -> -0.1788 | W60: Monthly Contrib. | Y60: ='Portfolio Projections'!B6 -> 1500
B98: Foward Income Expected Goals | S98: All times Portfolio Income Rank
B100: $1 a day | D100: $50 a month | F100: $100 a month | H100: $5 a day | J100: $200 a month | L100: $500 a month | N100: $1000 a month | P100: $2000 a month | S100: ✅ Top Dividend Payers | W100: ❌ Bottom Dividend Payers
S101: 1st | T101: {=INDEX('Dividend Log'!$B$2:$AF$2, MATCH(LARGE('Dividend Log'!$B$3:$AF$3, 1), 'Dividend Log'!$B$3:$AF$3, 0))} -> SCHD | V101: =LARGE('Dividend Log'!$B$3:$AF$3, 1) -> 197.34 | W101: 1st | X101: =IFERROR(__xludf.DUMMYFUNCTION("INDEX('Dividend Log'!$B$2:$AF$2, MATCH(SMALL(FILTER('Dividend Log'!$B$3:$AF$3,'Dividend Log'!$B$3:$AF$3>0), 1), 'Dividend Log'!$B$3:$AF$3, 0))"),"GOOGL") -> GOOGL | Z101: =IFERROR(__xludf.DUMMYFUNCTION("SMALL(FILTER('Dividend Log'!$B$3:$AF$3,'Dividend Log'!$B$3:$AF$3>0), 1)"),5.67) -> 5.67
B102: =IF($P$6/1>1, "✅ Achieved", "⏳ In Progress: " & TEXT($P$6/1, "0%")) -> ✅ Achieved | D102: =IF($P$4/50>1, "✅ Achieved", "⏳ In Progress: " & TEXT($P$4/50, "0%")) -> ✅ Achieved | F102: =IF($P$4/100>1, "✅ Achieved", "⏳ In Progress: " & TEXT($P$4/100, "0%")) -> ⏳ In Progress: 74% | H102: =IF($P$6/5>1, "✅ Achieved", "⏳ In Progress: " & TEXT($P$6/5, "0%")) -> ⏳ In Progress: 48% | J102: =IF($P$4/200>1, "✅ Achieved", "⏳ In Progress: " & TEXT($P$4/200, "0%")) -> ⏳ In Progress: 37% | L102: =IF($P$4/500>1, "✅ Achieved", "⏳ In Progress: " & TEXT($P$4/500, "0%")) -> ⏳ In Progress: 15% | N102: =IF($P$4/1000>1, "✅ Achieved", "⏳ In Progress: " & TEXT($P$4/1000, "0%")) -> ⏳ In Progress: 7% | P102: =IF($P$4/2000>1, "✅ Achieved", "⏳ In Progress: " & TEXT($P$4/2000, "0%")) -> ⏳ In Progress: 4%
S103: 2nd | T103: {=INDEX('Dividend Log'!$B$2:$AF$2, MATCH(LARGE('Dividend Log'!$B$3:$AF$3, 2), 'Dividend Log'!$B$3:$AF$3, 0))} -> SPAXX | V103: =LARGE('Dividend Log'!$B$3:$AF$3, 2) -> 180.66 | W103: 2nd | X103: =IFERROR(__xludf.DUMMYFUNCTION("INDEX('Dividend Log'!$B$2:$AF$2, MATCH(SMALL(FILTER('Dividend Log'!$B$3:$AF$3,'Dividend Log'!$B$3:$AF$3>0), 2), 'Dividend Log'!$B$3:$AF$3, 0))"),"VIG") -> VIG | Z103: =IFERROR(__xludf.DUMMYFUNCTION("SMALL(FILTER('Dividend Log'!$B$3:$AF$3,'Dividend Log'!$B$3:$AF$3>0), 2)"),6.25) -> 6.25
S105: 3rd | T105: {=INDEX('Dividend Log'!$B$2:$AF$2, MATCH(LARGE('Dividend Log'!$B$3:$AF$3, 3), 'Dividend Log'!$B$3:$AF$3, 0))} -> TGT | V105: =LARGE('Dividend Log'!$B$3:$AF$3, 3) -> 172.39 | W105: 3rd | X105: =IFERROR(__xludf.DUMMYFUNCTION("INDEX('Dividend Log'!$B$2:$AF$2, MATCH(SMALL(FILTER('Dividend Log'!$B$3:$AF$3,'Dividend Log'!$B$3:$AF$3>0), 3), 'Dividend Log'!$B$3:$AF$3, 0))"),"BND") -> BND | Z105: =IFERROR(__xludf.DUMMYFUNCTION("SMALL(FILTER('Dividend Log'!$B$3:$AF$3,'Dividend Log'!$B$3:$AF$3>0), 3)"),8.45) -> 8.45
S107: 4th | T107: {=INDEX('Dividend Log'!$B$2:$AF$2, MATCH(LARGE('Dividend Log'!$B$3:$AF$3, 4), 'Dividend Log'!$B$3:$AF$3, 0))} -> O | V107: =LARGE('Dividend Log'!$B$3:$AF$3, 4) -> 124 | W107: 4th | X107: =IFERROR(__xludf.DUMMYFUNCTION("INDEX('Dividend Log'!$B$2:$AF$2, MATCH(SMALL(FILTER('Dividend Log'!$B$3:$AF$3,'Dividend Log'!$B$3:$AF$3>0), 4), 'Dividend Log'!$B$3:$AF$3, 0))"),"VGT") -> VGT | Z107: =IFERROR(__xludf.DUMMYFUNCTION("SMALL(FILTER('Dividend Log'!$B$3:$AF$3,'Dividend Log'!$B$3:$AF$3>0), 4)"),10.16) -> 10.16
S109: 5th | T109: {=INDEX('Dividend Log'!$B$2:$AF$2, MATCH(LARGE('Dividend Log'!$B$3:$AF$3, 5), 'Dividend Log'!$B$3:$AF$3, 0))} -> VXUS | V109: =LARGE('Dividend Log'!$B$3:$AF$3, 5) -> 51.61 | W109: 5th | X109: =IFERROR(__xludf.DUMMYFUNCTION("INDEX('Dividend Log'!$B$2:$AF$2, MATCH(SMALL(FILTER('Dividend Log'!$B$3:$AF$3,'Dividend Log'!$B$3:$AF$3>0), 5), 'Dividend Log'!$B$3:$AF$3, 0))"),"SBUX") -> SBUX | Z109: =IFERROR(__xludf.DUMMYFUNCTION("SMALL(FILTER('Dividend Log'!$B$3:$AF$3,'Dividend Log'!$B$3:$AF$3>0), 5)"),12.43) -> 12.43
...

Sheet Claude Cache
A1: ⚠️ SHEET RESERVED FOR =CLAUDE... FUNCTIONS. DO NOT EDIT! ⚠️
A2: Key | B2: Value | C2: Expiration

Sheet Positions
A1: Ticker | B1: Company Name | C1: View On Seeking Alpha | D1: # of Shares | E1: Avg. Cost Per Share | F1: Share Price | G1: Intrinsic Value | H1: InvT Score | I1: Day Change / Share ($) | J1: Day Change / Share (%) | K1: Overall Day Change ($) | L1: 52 Week Low | M1: 52 Week Range | N1: 52 Week High | O1: Market Return ($) | P1: Total Return ($) | Q1: Market Return (%) | R1: Total Return (%) | S1: Security Type | T1: Sector | U1: Category | V1: Portfolio Allocation | W1: Annual Dividend | X1: Dividend Yield | Y1: Yield On Cost | Z1: 5 Year Dividend Growth Rate | AA1: Cost Basis | AB1: Market Value | AC1: Annual Dividend Income | AD1: Percentage of Total Income | AE1: Total Dividends Received | AF1: Annual Shares Purch. w/ Div. | AG1: Distance From Intrinsic Value | AH1: Intrinsic Value Signal | AI1: Distance From Avg. Cost | AJ1: Avg. Cost Signal | AK1: DO NOT DELETE THIS COLUMN
A2: GOOGL | B2: =IFERROR(__xludf.DUMMYFUNCTION("IF(ISBLANK(A2),"""", googlefinance(A2, ""name""))"),"Alphabet Inc Class A") -> Alphabet Inc Class A | C2: =IF(ISBLANK(A2),"", HYPERLINK("https://seekingalpha.com/symbol/" & A2,"View")) -> View | D2: 9.025 | E2: 154.48 | F2: =IFERROR(__xludf.DUMMYFUNCTION("IF(ISBLANK(A2),"""", googlefinance(A2, ""price""))"),300.88) -> 300.88 | G2: =IF(ISBLANK(A2),"",IFERROR(VLOOKUP(A2, 'Intrinsic Values List'!$A$2:$D$70, 4, FALSE), "Not Found" )) -> 187.26 | H2: =IF(ISBLANK(A2),"",IFERROR(VLOOKUP(A2, 'Intrinsic Values List'!$A$2:$G$70, 7, FALSE), "Not Found" )) -> 8.58 | I2: =IFERROR(__xludf.DUMMYFUNCTION("IFERROR(googlefinance(A2,""change""),"""")"),-2.25) -> -2.25 | J2: =IFERROR(__xludf.DUMMYFUNCTION("iferror(GOOGLEFINANCE(A2,""changepct"")/100,"""")"),-0.0074) -> -0.0074 | K2: =if(isblank(A2),"",(D2*I2)) -> -20.30625 | L2: =IFERROR(__xludf.DUMMYFUNCTION("IF(ISBLANK(A2),"""", googlefinance(A2, ""low52""))"),140.53) -> 140.53 | M2: =IFERROR(__xludf.DUMMYFUNCTION("IF(ISBLANK(A2),"""",IFERROR(SPARKLINE((F2-L2)/(N2-L2),{""charttype"",""bar"";""max"",1;""min"",0;""color1"",""2c79b5""}),""n/a""))"),"") | N2: =IFERROR(__xludf.DUMMYFUNCTION("IF(ISBLANK(A2),"""", googlefinance(A2, ""high52""))"),349.0) -> 349 | O2: =if(isblank(A2),"",(F2-E2)*D2) -> 1321.26 | P2: =if(isblank(A2),"",O2+AE2) -> 1326.93 | Q2: =iferror(if(D2<0,0,O2/(E2*D2)),"") -> 0.94769549 | R2: =if(isblank(A2),"",P2/(E2*D2)) -> 0.9517624 | S2: Stocks | T2: Information Technology | U2: Growth | V2: =if(isblank(A2),"",AB2/$AB$32) -> 0.067370077 | W2: =IFERROR(__xludf.DUMMYFUNCTION("IfError(IF(isblank(A2),"""",split(AK2, ""()"")))"),0.83) -> 0.83 | X2: =IFERROR(__xludf.DUMMYFUNCTION("""COMPUTED_VALUE"""),0.0028) -> 0.0028 | Y2: =IFERROR(W2/E2,"") -> 0.0053728638 | Z2: 0 | AA2: =iferror(if(isblank(A2),"",D2*E2),0) -> 1394.182 | AB2: =IF(ISBLANK(A2),"",D2*F2) -> 2715.442 | AC2: =IFERROR(IF(ISBLANK(A2),"",D2*W2),"") -> 7.49075 | AD2: =if(isblank(A2),"",AC2/$AC$32) -> 0.0084867363 | AE2: =IF(ISBLANK($A2),"",SUM(OFFSET('Dividend Log'!$B$17, 0, ROW($A2)-2), OFFSET('Dividend Log'!$B$31, 0, ROW($A2)-2), OFFSET('Dividend Log'!$B$45, 0, ROW($A2)-2), OFFSET('Dividend Log'!$B$59, 0, ROW($A2)-2), OFFSET('Dividend Log'!$B$73, 0, ROW($A2)-2))) -> 5.67 | AF2: =IFERROR(AC2/F2,"") -> 0.024896138 | AG2: =iferror(IF(ISBLANK(G2),"",(F2-G2)/G2),"") -> 0.60674997 | AH2: =IF(AG2="", "", IF(AG2<=-15%, "Strong Buy", IF(AG2<0%, "Buy", IF(AG2<=15%, "Expensive", "Overrated")))) -> Overrated | AI2: =IF(ISBLANK(A2),"",(F2-E2)/E2) -> 0.94769549 | AJ2: =IF(A2="", "", IF(AI2<-15%, "Strong Buy", IF(AI2<-5%, "Buy", IF(AI2<5%, "Avg. Cost", IF(AI2<=15%, "Overcost", "Hold"))))) -> Hold | AK2: =IFERROR(__xludf.DUMMYFUNCTION("LET(t, A2, IF(t="""","""", IFERROR( SUBSTITUTE( INDEX( IMPORTXML( ""https://finviz.com/quote.ashx?t=""&t&""&ty=dv"", ""(//td[normalize-space()='Dividend TTM' or contains(.,'Dividend TTM')]/following-si"&"bling::td[1])[1]"" ),1,1), ""*"",""""), IFERROR( SUBSTITUTE( INDEX( IMPORTXML( ""https://finviz.com/quote.ashx?t=""&t, ""(//td[normalize-space()='Dividend']/following-sibling:"&":td[1])[1]"" ),1,1), ""*"",""""), """") ) ) ) "),"0.83 (0.28%)") -> 0.83 (0.28%)
A3: MSFT | B3: =IFERROR(__xludf.DUMMYFUNCTION("IF(ISBLANK(A3),"""", googlefinance(A3, ""name""))"),"Microsoft Corp") -> Microsoft Corp | C3: =IF(ISBLANK(A3),"", HYPERLINK("https://seekingalpha.com/symbol/" & A3,"View")) -> View | D3: 9.552 | E3: 393.4 | F3: =IFERROR(__xludf.DUMMYFUNCTION("IF(ISBLANK(A3),"""", googlefinance(A3, ""price""))"),410.68) -> 410.68 | G3: =IF(ISBLANK(A3),"",IFERROR(VLOOKUP(A3, 'Intrinsic Values List'!$A$2:$D$70, 4, FALSE), "Not Found" )) -> 334 | H3: =IF(ISBLANK(A3),"",IFERROR(VLOOKUP(A3, 'Intrinsic Values List'!$A$2:$G$70, 7, FALSE), "Not Found" )) -> 8.74 | I3: =IFERROR(__xludf.DUMMYFUNCTION("IFERROR(googlefinance(A3,""change""),"""")"),5.48) -> 5.48 | J3: =IFERROR(__xludf.DUMMYFUNCTION("iferror(GOOGLEFINANCE(A3,""changepct"")/100,"""")"),0.013500000000000002) -> 0.0135 | K3: =if(isblank(A3),"",(D3*I3)) -> 52.34496 | L3: =IFERROR(__xludf.DUMMYFUNCTION("IF(ISBLANK(A3),"""", googlefinance(A3, ""low52""))"),344.79) -> 344.79 | M3: =IFERROR(__xludf.DUMMYFUNCTION("IF(ISBLANK(A3),"""",IFERROR(SPARKLINE((F3-L3)/(N3-L3),{""charttype"",""bar"";""max"",1;""min"",0;""color1"",""2c79b5""}),""n/a""))"),"") | N3: =IFERROR(__xludf.DUMMYFUNCTION("IF(ISBLANK(A3),"""", googlefinance(A3, ""high52""))"),555.45) -> 555.45 | O3: =if(isblank(A3),"",(F3-E3)*D3) -> 165.05856 | P3: =if(isblank(A3),"",O3+AE3) -> 198.08856 | Q3: =iferror(if(D3<0,0,O3/(E3*D3)),"") -> 0.043924759 | R3: =if(isblank(A3),"",P3/(E3*D3)) -> 0.052714577 | S3: Stocks | T3: Information Technology | U3: Growth | V3: =if(isblank(A3),"",AB3/$AB$32) -> 0.097324993 | W3: =IFERROR(__xludf.DUMMYFUNCTION("IfError(IF(isblank(A3),"""",split(AK3, ""()"")))"),"") | Y3: =IFERROR(W3/E3,"") -> 0 | Z3: 0.102 | AA3: =iferror(if(isblank(A3),"",D3*E3),0) -> 3757.7568 | AB3: =IF(ISBLANK(A3),"",D3*F3) -> 3922.8154 | AC3: =IFERROR(IF(ISBLANK(A3),"",D3*W3),"") -> 0 | AD3: =if(isblank(A3),"",AC3/$AC$32) -> 0 | AE3: =IF(ISBLANK($A3),"",SUM(OFFSET('Dividend Log'!$B$17, 0, ROW($A3)-2), OFFSET('Dividend Log'!$B$31, 0, ROW($A3)-2), OFFSET('Dividend Log'!$B$45, 0, ROW($A3)-2), OFFSET('Dividend Log'!$B$59, 0, ROW($A3)-2), OFFSET('Dividend Log'!$B$73, 0, ROW($A3)-2))) -> 33.03 | AF3: =IFERROR(AC3/F3,"") -> 0 | AG3: =iferror(IF(ISBLANK(G3),"",(F3-G3)/G3),"") -> 0.22958084 | AH3: =IF(AG3="", "", IF(AG3<=-15%, "Strong Buy", IF(AG3<0%, "Buy", IF(AG3<=15%, "Expensive", "Overrated")))) -> Overrated | AI3: =IF(ISBLANK(A3),"",(F3-E3)/E3) -> 0.043924759 | AJ3: =IF(A3="", "", IF(AI3<-15%, "Strong Buy", IF(AI3<-5%, "Buy", IF(AI3<5%, "Avg. Cost", IF(AI3<=15%, "Overcost", "Hold"))))) -> Avg. Cost | AK3: =IFERROR(__xludf.DUMMYFUNCTION("LET(t, A3, IF(t="""","""", IFERROR( SUBSTITUTE( INDEX( IMPORTXML( ""https://finviz.com/quote.ashx?t=""&t&""&ty=dv"", ""(//td[normalize-space()='Dividend TTM' or contains(.,'Dividend TTM')]/following-si"&"bling::td[1])[1]"" ),1,1), ""*"",""""), IFERROR( SUBSTITUTE( INDEX( IMPORTXML( ""https://finviz.com/quote.ashx?t=""&t, ""(//td[normalize-space()='Dividend']/following-sibling:"&":td[1])[1]"" ),1,1), ""*"",""""), """") ) ) ) "),"")
A4: DIS | B4: =IFERROR(__xludf.DUMMYFUNCTION("IF(ISBLANK(A4),"""", googlefinance(A4, ""name""))"),"Walt Disney Co") -> Walt Disney Co | C4: =IF(ISBLANK(A4),"", HYPERLINK("https://seekingalpha.com/symbol/" & A4,"View")) -> View | D4: 17.264 | E4: 93.48 | F4: =IFERROR(__xludf.DUMMYFUNCTION("IF(ISBLANK(A4),"""", googlefinance(A4, ""price""))"),102.41) -> 102.41 | G4: =IF(ISBLANK(A4),"",IFERROR(VLOOKUP(A4, 'Intrinsic Values List'!$A$2:$D$70, 4, FALSE), "Not Found" )) -> 89.15 | H4: =IF(ISBLANK(A4),"",IFERROR(VLOOKUP(A4, 'Intrinsic Values List'!$A$2:$G$70, 7, FALSE), "Not Found" )) -> 3.29 | I4: =IFERROR(__xludf.DUMMYFUNCTION("IFERROR(googlefinance(A4,""change""),"""")"),-0.63) -> -0.63 | J4: =IFERROR(__xludf.DUMMYFUNCTION("iferror(GOOGLEFINANCE(A4,""changepct"")/100,"""")"),-0.0060999999999999995) -> -0.0061 | K4: =if(isblank(A4),"",(D4*I4)) -> -10.87632 | L4: =IFERROR(__xludf.DUMMYFUNCTION("IF(ISBLANK(A4),"""", googlefinance(A4, ""low52""))"),80.1) -> 80.1 | M4: =IFERROR(__xludf.DUMMYFUNCTION("IF(ISBLANK(A4),"""",IFERROR(SPARKLINE((F4-L4)/(N4-L4),{""charttype"",""bar"";""max"",1;""min"",0;""color1"",""2c79b5""}),""n/a""))"),"") | N4: =IFERROR(__xludf.DUMMYFUNCTION("IF(ISBLANK(A4),"""", googlefinance(A4, ""high52""))"),124.69) -> 124.69 | O4: =if(isblank(A4),"",(F4-E4)*D4) -> 154.16752 | P4: =if(isblank(A4),"",O4+AE4) -> 183.87752 | Q4: =iferror(if(D4<0,0,O4/(E4*D4)),"") -> 0.095528455 | R4: =if(isblank(A4),"",P4/(E4*D4)) -> 0.11393798 | S4: Stocks | T4: Communication Services | U4: Growth | V4: =if(isblank(A4),"",AB4/$AB$32) -> 0.04386421 | W4: =IFERROR(__xludf.DUMMYFUNCTION("IfError(IF(isblank(A4),"""",split(AK4, ""()"")))"),1.25) -> 1.25 | X4: =IFERROR(__xludf.DUMMYFUNCTION("""COMPUTED_VALUE"""),0.0122) -> 0.0122 | Y4: =IFERROR(W4/E4,"") -> 0.013371844 | Z4: -0.2948 | AA4: =iferror(if(isblank(A4),"",D4*E4),0) -> 1613.8387 | AB4: =IF(ISBLANK(A4),"",D4*F4) -> 1768.0062 | AC4: =IFERROR(IF(ISBLANK(A4),"",D4*W4),"") -> 21.58 | AD4: =if(isblank(A4),"",AC4/$AC$32) -> 0.024449323 | AE4: =IF(ISBLANK($A4),"",SUM(OFFSET('Dividend Log'!$B$17, 0, ROW($A4)-2), OFFSET('Dividend Log'!$B$31, 0, ROW($A4)-2), OFFSET('Dividend Log'!$B$45, 0, ROW($A4)-2), OFFSET('Dividend Log'!$B$59, 0, ROW($A4)-2), OFFSET('Dividend Log'!$B$73, 0, ROW($A4)-2))) -> 29.71 | AF4: =IFERROR(AC4/F4,"") -> 0.21072161 | AG4: =iferror(IF(ISBLANK(G4),"",(F4-G4)/G4),"") -> 0.14873808 | AH4: =IF(AG4="", "", IF(AG4<=-15%, "Strong Buy", IF(AG4<0%, "Buy", IF(AG4<=15%, "Expensive", "Overrated")))) -> Expensive | AI4: =IF(ISBLANK(A4),"",(F4-E4)/E4) -> 0.095528455 | AJ4: =IF(A4="", "", IF(AI4<-15%, "Strong Buy", IF(AI4<-5%, "Buy", IF(AI4<5%, "Avg. Cost", IF(AI4<=15%, "Overcost", "Hold"))))) -> Overcost | AK4: =IFERROR(__xludf.DUMMYFUNCTION("LET(t, A4, IF(t="""","""", IFERROR( SUBSTITUTE( INDEX( IMPORTXML( ""https://finviz.com/quote.ashx?t=""&t&""&ty=dv"", ""(//td[normalize-space()='Dividend TTM' or contains(.,'Dividend TTM')]/following-si"&"bling::td[1])[1]"" ),1,1), ""*"",""""), IFERROR( SUBSTITUTE( INDEX( IMPORTXML( ""https://finviz.com/quote.ashx?t=""&t, ""(//td[normalize-space()='Dividend']/following-sibling:"&":td[1])[1]"" ),1,1), ""*"",""""), """") ) ) ) "),"1.25 (1.22%)") -> 1.25 (1.22%)
A5: TGT | B5: =IFERROR(__xludf.DUMMYFUNCTION("IF(ISBLANK(A5),"""", googlefinance(A5, ""name""))"),"Target Corp") -> Target Corp | C5: =IF(ISBLANK(A5),"", HYPERLINK("https://seekingalpha.com/symbol/" & A5,"View")) -> View | D5: 31.358 | E5: 117.78 | F5: =IFERROR(__xludf.DUMMYFUNCTION("IF(ISBLANK(A5),"""", googlefinance(A5, ""price""))"),120.36) -> 120.36 | G5: =IF(ISBLANK(A5),"",IFERROR(VLOOKUP(A5, 'Intrinsic Values List'!$A$2:$D$70, 4, FALSE), "Not Found" )) -> 226.6 | H5: =IF(ISBLANK(A5),"",IFERROR(VLOOKUP(A5, 'Intrinsic Values List'!$A$2:$G$70, 7, FALSE), "Not Found" )) -> 6.59 | I5: =IFERROR(__xludf.DUMMYFUNCTION("IFERROR(googlefinance(A5,""change""),"""")"),0.28) -> 0.28 | J5: =IFERROR(__xludf.DUMMYFUNCTION("iferror(GOOGLEFINANCE(A5,""changepct"")/100,"""")"),0.0023) -> 0.0023 | K5: =if(isblank(A5),"",(D5*I5)) -> 8.78024 | L5: =IFERROR(__xludf.DUMMYFUNCTION("IF(ISBLANK(A5),"""", googlefinance(A5, ""low52""))"),83.44) -> 83.44 | M5: =IFERROR(__xludf.DUMMYFUNCTION("IF(ISBLANK(A5),"""",IFERROR(SPARKLINE((F5-L5)/(N5-L5),{""charttype"",""bar"";""max"",1;""min"",0;""color1"",""2c79b5""}),""n/a""))"),"") | N5: =IFERROR(__xludf.DUMMYFUNCTION("IF(ISBLANK(A5),"""", googlefinance(A5, ""high52""))"),126.0) -> 126 | O5: =if(isblank(A5),"",(F5-E5)*D5) -> 80.90364 | P5: =if(isblank(A5),"",O5+AE5) -> 253.29364 | Q5: =iferror(if(D5<0,0,O5/(E5*D5)),"") -> 0.021905247 | R5: =if(isblank(A5),"",P5/(E5*D5)) -> 0.068581089 | S5: Stocks | T5: Consumer Staples | U5: Growth | V5: =if(isblank(A5),"",AB5/$AB$32) -> 0.093639061 | W5: =IFERROR(__xludf.DUMMYFUNCTION("IfError(IF(isblank(A5),"""",split(AK5, ""()"")))"),4.54) -> 4.54 | X5: =IFERROR(__xludf.DUMMYFUNCTION("""COMPUTED_VALUE"""),0.0377) -> 0.0377 | Y5: =IFERROR(W5/E5,"") -> 0.038546443 | Z5: 0.1151 | AA5: =iferror(if(isblank(A5),"",D5*E5),0) -> 3693.3452 | AB5: =IF(ISBLANK(A5),"",D5*F5) -> 3774.2489 | AC5: =IFERROR(IF(ISBLANK(A5),"",D5*W5),"") -> 142.36532 | AD5: =if(isblank(A5),"",AC5/$AC$32) -> 0.16129452 | AE5: =IF(ISBLANK($A5),"",SUM(OFFSET('Dividend Log'!$B$17, 0, ROW($A5)-2), OFFSET('Dividend Log'!$B$31, 0, ROW($A5)-2), OFFSET('Dividend Log'!$B$45, 0, ROW($A5)-2), OFFSET('Dividend Log'!$B$59, 0, ROW($A5)-2), OFFSET('Dividend Log'!$B$73, 0, ROW($A5)-2))) -> 172.39 | AF5: =IFERROR(AC5/F5,"") -> 1.1828292 | AG5: =iferror(IF(ISBLANK(G5),"",(F5-G5)/G5),"") -> -0.46884378 | AH5: =IF(AG5="", "", IF(AG5<=-15%, "Strong Buy", IF(AG5<0%, "Buy", IF(AG5<=15%, "Expensive", "Overrated")))) -> Strong Buy | AI5: =IF(ISBLANK(A5),"",(F5-E5)/E5) -> 0.021905247 | AJ5: =IF(A5="", "", IF(AI5<-15%, "Strong Buy", IF(AI5<-5%, "Buy", IF(AI5<5%, "Avg. Cost", IF(AI5<=15%, "Overcost", "Hold"))))) -> Avg. Cost | AK5: =IFERROR(__xludf.DUMMYFUNCTION("LET(t, A5, IF(t="""","""", IFERROR( SUBSTITUTE( INDEX( IMPORTXML( ""https://finviz.com/quote.ashx?t=""&t&""&ty=dv"", ""(//td[normalize-space()='Dividend TTM' or contains(.,'Dividend TTM')]/following-si"&"bling::td[1])[1]"" ),1,1), ""*"",""""), IFERROR( SUBSTITUTE( INDEX( IMPORTXML( ""https://finviz.com/quote.ashx?t=""&t, ""(//td[normalize-space()='Dividend']/following-sibling:"&":td[1])[1]"" ),1,1), ""*"",""""), """") ) ) ) "),"4.54 (3.77%)") -> 4.54 (3.77%)
A6: SBUX | B6: =IFERROR(__xludf.DUMMYFUNCTION("IF(ISBLANK(A6),"""", googlefinance(A6, ""name""))"),"Starbucks Corp") -> Starbucks Corp | C6: =IF(ISBLANK(A6),"", HYPERLINK("https://seekingalpha.com/symbol/" & A6,"View")) -> View | D6: 5.071 | E6: 81.62 | F6: =IFERROR(__xludf.DUMMYFUNCTION("IF(ISBLANK(A6),"""", googlefinance(A6, ""price""))"),98.69) -> 98.69 | G6: =IF(ISBLANK(A6),"",IFERROR(VLOOKUP(A6, 'Intrinsic Values List'!$A$2:$D$70, 4, FALSE), "Not Found" )) -> 89.57 | H6: =IF(ISBLANK(A6),"",IFERROR(VLOOKUP(A6, 'Intrinsic Values List'!$A$2:$G$70, 7, FALSE), "Not Found" )) -> 5.17 | I6: =IFERROR(__xludf.DUMMYFUNCTION("IFERROR(googlefinance(A6,""change""),"""")"),1.54) -> 1.54 | J6: =IFERROR(__xludf.DUMMYFUNCTION("iferror(GOOGLEFINANCE(A6,""changepct"")/100,"""")"),0.0159) -> 0.0159 | K6: =if(isblank(A6),"",(D6*I6)) -> 7.80934 | L6: =IFERROR(__xludf.DUMMYFUNCTION("IF(ISBLANK(A6),"""", googlefinance(A6, ""low52""))"),75.5) -> 75.5 | M6: =IFERROR(__xludf.DUMMYFUNCTION("IF(ISBLANK(A6),"""",IFERROR(SPARKLINE((F6-L6)/(N6-L6),{""charttype"",""bar"";""max"",1;""min"",0;""color1"",""2c79b5""}),""n/a""))"),"") | N6: =IFERROR(__xludf.DUMMYFUNCTION("IF(ISBLANK(A6),"""", googlefinance(A6, ""high52""))"),110.43) -> 110.43 | O6: =if(isblank(A6),"",(F6-E6)*D6) -> 86.56197 | P6: =if(isblank(A6),"",O6+AE6) -> 98.99197 | Q6: =iferror(if(D6<0,0,O6/(E6*D6)),"") -> 0.20913992 | R6: =if(isblank(A6),"",P6/(E6*D6)) -> 0.23917169 | S6: Stocks | T6: Consumer Discretionary | U6: Growth | V6: =if(isblank(A6),"",AB6/$AB$32) -> 0.012416331 | W6: =IFERROR(__xludf.DUMMYFUNCTION("IfError(IF(isblank(A6),"""",split(AK6, ""()"")))"),2.46) -> 2.46 | X6: =IFERROR(__xludf.DUMMYFUNCTION("""COMPUTED_VALUE"""),0.0249) -> 0.0249 | Y6: =IFERROR(W6/E6,"") -> 0.030139672 | Z6: 0.075 | AA6: =iferror(if(isblank(A6),"",D6*E6),0) -> 413.89502 | AB6: =IF(ISBLANK(A6),"",D6*F6) -> 500.45699 | AC6: =IFERROR(IF(ISBLANK(A6),"",D6*W6),"") -> 12.47466 | AD6: =if(isblank(A6),"",AC6/$AC$32) -> 0.014133318 | AE6: =IF(ISBLANK($A6),"",SUM(OFFSET('Dividend Log'!$B$17, 0, ROW($A6)-2), OFFSET('Dividend Log'!$B$31, 0, ROW($A6)-2), OFFSET('Dividend Log'!$B$45, 0, ROW($A6)-2), OFFSET('Dividend Log'!$B$59, 0, ROW($A6)-2), OFFSET('Dividend Log'!$B$73, 0, ROW($A6)-2))) -> 12.43 | AF6: =IFERROR(AC6/F6,"") -> 0.12640247 | AG6: =iferror(IF(ISBLANK(G6),"",(F6-G6)/G6),"") -> 0.10181981 | AH6: =IF(AG6="", "", IF(AG6<=-15%, "Strong Buy", IF(AG6<0%, "Buy", IF(AG6<=15%, "Expensive", "Overrated")))) -> Expensive | AI6: =IF(ISBLANK(A6),"",(F6-E6)/E6) -> 0.20913992 | AJ6: =IF(A6="", "", IF(AI6<-15%, "Strong Buy", IF(AI6<-5%, "Buy", IF(AI6<5%, "Avg. Cost", IF(AI6<=15%, "Overcost", "Hold"))))) -> Hold | AK6: =IFERROR(__xludf.DUMMYFUNCTION("LET(t, A6, IF(t="""","""", IFERROR( SUBSTITUTE( INDEX( IMPORTXML( ""https://finviz.com/quote.ashx?t=""&t&""&ty=dv"", ""(//td[normalize-space()='Dividend TTM' or contains(.,'Dividend TTM')]/following-si"&"bling::td[1])[1]"" ),1,1), ""*"",""""), IFERROR( SUBSTITUTE( INDEX( IMPORTXML( ""https://finviz.com/quote.ashx?t=""&t, ""(//td[normalize-space()='Dividend']/following-sibling:"&":td[1])[1]"" ),1,1), ""*"",""""), """") ) ) ) "),"2.46 (2.49%)") -> 2.46 (2.49%)
A7: JPM | B7: =IFERROR(__xludf.DUMMYFUNCTION("IF(ISBLANK(A7),"""", googlefinance(A7, ""name""))"),"JPMorgan Chase & Co") -> JPMorgan Chase & Co | C7: =IF(ISBLANK(A7),"", HYPERLINK("https://seekingalpha.com/symbol/" & A7,"View")) -> View | D7: 2.057 | E7: 199.07 | F7: =IFERROR(__xludf.DUMMYFUNCTION("IF(ISBLANK(A7),"""", googlefinance(A7, ""price""))"),293.55) -> 293.55 | G7: =IF(ISBLANK(A7),"",IFERROR(VLOOKUP(A7, 'Intrinsic Values List'!$A$2:$D$70, 4, FALSE), "Not Found" )) -> 287.74 | H7: =IF(ISBLANK(A7),"",IFERROR(VLOOKUP(A7, 'Intrinsic Values List'!$A$2:$G$70, 7, FALSE), "Not Found" )) -> 6.82 | I7: =IFERROR(__xludf.DUMMYFUNCTION("IFERROR(googlefinance(A7,""change""),"""")"),-5.84) -> -5.84 | J7: =IFERROR(__xludf.DUMMYFUNCTION("iferror(GOOGLEFINANCE(A7,""changepct"")/100,"""")"),-0.0195) -> -0.0195 | K7: =if(isblank(A7),"",(D7*I7)) -> -12.01288 | L7: =IFERROR(__xludf.DUMMYFUNCTION("IF(ISBLANK(A7),"""", googlefinance(A7, ""low52""))"),202.16) -> 202.16 | M7: =IFERROR(__xludf.DUMMYFUNCTION("IF(ISBLANK(A7),"""",IFERROR(SPARKLINE((F7-L7)/(N7-L7),{""charttype"",""bar"";""max"",1;""min"",0;""color1"",""2c79b5""}),""n/a""))"),"") | N7: =IFERROR(__xludf.DUMMYFUNCTION("IF(ISBLANK(A7),"""", googlefinance(A7, ""high52""))"),337.25) -> 337.25 | O7: =if(isblank(A7),"",(F7-E7)*D7) -> 194.34536 | P7: =if(isblank(A7),"",O7+AE7) -> 212.37536 | Q7: =iferror(if(D7<0,0,O7/(E7*D7)),"") -> 0.47460692 | R7: =if(isblank(A7),"",P7/(E7*D7)) -> 0.51863763 | S7: Stocks | T7: Financials | U7: Value Stocks | V7: =if(isblank(A7),"",AB7/$AB$32) -> 0.014981072 | W7: =IFERROR(__xludf.DUMMYFUNCTION("IfError(IF(isblank(A7),"""",split(AK7, ""()"")))"),5.8) -> 5.8 | X7: =IFERROR(__xludf.DUMMYFUNCTION("""COMPUTED_VALUE"""),0.0198) -> 0.0198 | Y7: =IFERROR(W7/E7,"") -> 0.02913548 | Z7: 0.075 | AA7: =iferror(if(isblank(A7),"",D7*E7),0) -> 409.48699 | AB7: =IF(ISBLANK(A7),"",D7*F7) -> 603.83235 | AC7: =IFERROR(IF(ISBLANK(A7),"",D7*W7),"") -> 11.9306 | AD7: =if(isblank(A7),"",AC7/$AC$32) -> 0.013516918 | AE7: =IF(ISBLANK($A7),"",SUM(OFFSET('Dividend Log'!$B$17, 0, ROW($A7)-2), OFFSET('Dividend Log'!$B$31, 0, ROW($A7)-2), OFFSET('Dividend Log'!$B$45, 0, ROW($A7)-2), OFFSET('Dividend Log'!$B$59, 0, ROW($A7)-2), OFFSET('Dividend Log'!$B$73, 0, ROW($A7)-2))) -> 18.03 | AF7: =IFERROR(AC7/F7,"") -> 0.04064248 | AG7: =iferror(IF(ISBLANK(G7),"",(F7-G7)/G7),"") -> 0.02019184 | AH7: =IF(AG7="", "", IF(AG7<=-15%, "Strong Buy", IF(AG7<0%, "Buy", IF(AG7<=15%, "Expensive", "Overrated")))) -> Expensive | AI7: =IF(ISBLANK(A7),"",(F7-E7)/E7) -> 0.47460692 | AJ7: =IF(A7="", "", IF(AI7<-15%, "Strong Buy", IF(AI7<-5%, "Buy", IF(AI7<5%, "Avg. Cost", IF(AI7<=15%, "Overcost", "Hold"))))) -> Hold | AK7: =IFERROR(__xludf.DUMMYFUNCTION("LET(t, A7, IF(t="""","""", IFERROR( SUBSTITUTE( INDEX( IMPORTXML( ""https://finviz.com/quote.ashx?t=""&t&""&ty=dv"", ""(//td[normalize-space()='Dividend TTM' or contains(.,'Dividend TTM')]/following-si"&"bling::td[1])[1]"" ),1,1), ""*"",""""), IFERROR( SUBSTITUTE( INDEX( IMPORTXML( ""https://finviz.com/quote.ashx?t=""&t, ""(//td[normalize-space()='Dividend']/following-sibling:"&":td[1])[1]"" ),1,1), ""*"",""""), """") ) ) ) "),"5.80 (1.98%)") -> 5.80 (1.98%)
A8: KO | B8: =IFERROR(__xludf.DUMMYFUNCTION("IF(ISBLANK(A8),"""", googlefinance(A8, ""name""))"),"Coca-Cola Co") -> Coca-Cola Co | C8: =IF(ISBLANK(A8),"", HYPERLINK("https://seekingalpha.com/symbol/" & A8,"View")) -> View | D8: 11.418 | E8: 63.85 | F8: =IFERROR(__xludf.DUMMYFUNCTION("IF(ISBLANK(A8),"""", googlefinance(A8, ""price""))"),77.03) -> 77.03 | G8: =IF(ISBLANK(A8),"",IFERROR(VLOOKUP(A8, 'Intrinsic Values List'!$A$2:$D$70, 4, FALSE), "Not Found" )) -> 40.7 | H8: =IF(ISBLANK(A8),"",IFERROR(VLOOKUP(A8, 'Intrinsic Values List'!$A$2:$G$70, 7, FALSE), "Not Found" )) -> 6 | I8: =IFERROR(__xludf.DUMMYFUNCTION("IFERROR(googlefinance(A8,""change""),"""")"),-1.07) -> -1.07 | J8: =IFERROR(__xludf.DUMMYFUNCTION("iferror(GOOGLEFINANCE(A8,""changepct"")/100,"""")"),-0.0137) -> -0.0137 | K8: =if(isblank(A8),"",(D8*I8)) -> -12.21726 | L8: =IFERROR(__xludf.DUMMYFUNCTION("IF(ISBLANK(A8),"""", googlefinance(A8, ""low52""))"),65.35) -> 65.35 | M8: =IFERROR(__xludf.DUMMYFUNCTION("IF(ISBLANK(A8),"""",IFERROR(SPARKLINE((F8-L8)/(N8-L8),{""charttype"",""bar"";""max"",1;""min"",0;""color1"",""2c79b5""}),""n/a""))"),"") | N8: =IFERROR(__xludf.DUMMYFUNCTION("IF(ISBLANK(A8),"""", googlefinance(A8, ""high52""))"),82.0) -> 82 | O8: =if(isblank(A8),"",(F8-E8)*D8) -> 150.48924 | P8: =if(isblank(A8),"",O8+AE8) -> 179.22924 | Q8: =iferror(if(D8<0,0,O8/(E8*D8)),"") -> 0.2064213 | R8: =if(isblank(A8),"",P8/(E8*D8)) -> 0.24584304 | S8: Stocks | T8: Consumer Staples | U8: Value Stocks | V8: =if(isblank(A8),"",AB8/$AB$32) -> 0.021821091 | W8: =IFERROR(__xludf.DUMMYFUNCTION("IfError(IF(isblank(A8),"""",split(AK8, ""()"")))"),2.04) -> 2.04 | X8: =IFERROR(__xludf.DUMMYFUNCTION("""COMPUTED_VALUE"""),0.0265) -> 0.0265 | Y8: =IFERROR(W8/E8,"") -> 0.031949883 | Z8: 0.035 | AA8: =iferror(if(isblank(A8),"",D8*E8),0) -> 729.0393 | AB8: =IF(ISBLANK(A8),"",D8*F8) -> 879.52854 | AC8: =IFERROR(IF(ISBLANK(A8),"",D8*W8),"") -> 23.29272 | AD8: =if(isblank(A8),"",AC8/$AC$32) -> 0.02638977 | AE8: =IF(ISBLANK($A8),"",SUM(OFFSET('Dividend Log'!$B$17, 0, ROW($A8)-2), OFFSET('Dividend Log'!$B$31, 0, ROW($A8)-2), OFFSET('Dividend Log'!$B$45, 0, ROW($A8)-2), OFFSET('Dividend Log'!$B$59, 0, ROW($A8)-2), OFFSET('Dividend Log'!$B$73, 0, ROW($A8)-2))) -> 28.74 | AF8: =IFERROR(AC8/F8,"") -> 0.30238504 | AG8: =iferror(IF(ISBLANK(G8),"",(F8-G8)/G8),"") -> 0.89262899 | AH8: =IF(AG8="", "", IF(AG8<=-15%, "Strong Buy", IF(AG8<0%, "Buy", IF(AG8<=15%, "Expensive", "Overrated")))) -> Overrated | AI8: =IF(ISBLANK(A8),"",(F8-E8)/E8) -> 0.2064213 | AJ8: =IF(A8="", "", IF(AI8<-15%, "Strong Buy", IF(AI8<-5%, "Buy", IF(AI8<5%, "Avg. Cost", IF(AI8<=15%, "Overcost", "Hold"))))) -> Hold | AK8: =IFERROR(__xludf.DUMMYFUNCTION("LET(t, A8, IF(t="""","""", IFERROR( SUBSTITUTE( INDEX( IMPORTXML( ""https://finviz.com/quote.ashx?t=""&t&""&ty=dv"", ""(//td[normalize-space()='Dividend TTM' or contains(.,'Dividend TTM')]/following-si"&"bling::td[1])[1]"" ),1,1), ""*"",""""), IFERROR( SUBSTITUTE( INDEX( IMPORTXML( ""https://finviz.com/quote.ashx?t=""&t, ""(//td[normalize-space()='Dividend']/following-sibling:"&":td[1])[1]"" ),1,1), ""*"",""""), """") ) ) ) "),"2.04 (2.65%)") -> 2.04 (2.65%)
A9: O | B9: =IFERROR(__xludf.DUMMYFUNCTION("IF(ISBLANK(A9),"""", googlefinance(A9, ""name""))"),"Realty Income Corp") -> Realty Income Corp | C9: =IF(ISBLANK(A9),"", HYPERLINK("https://seekingalpha.com/symbol/" & A9,"View")) -> View | D9: 31.001 | E9: 54.62 | F9: =IFERROR(__xludf.DUMMYFUNCTION("IF(ISBLANK(A9),"""", googlefinance(A9, ""price""))"),64.8) -> 64.8 | G9: =IF(ISBLANK(A9),"",IFERROR(VLOOKUP(A9, 'Intrinsic Values List'!$A$2:$D$70, 4, FALSE), "Not Found" )) -> 33.62 | H9: =IF(ISBLANK(A9),"",IFERROR(VLOOKUP(A9, 'Intrinsic Values List'!$A$2:$G$70, 7, FALSE), "Not Found" )) -> 3.92 | I9: =IFERROR(__xludf.DUMMYFUNCTION("IFERROR(googlefinance(A9,""change""),"""")"),-1.2) -> -1.2 | J9: =IFERROR(__xludf.DUMMYFUNCTION("iferror(GOOGLEFINANCE(A9,""changepct"")/100,"""")"),-0.0182) -> -0.0182 | K9: =if(isblank(A9),"",(D9*I9)) -> -37.2012 | L9: =IFERROR(__xludf.DUMMYFUNCTION("IF(ISBLANK(A9),"""", googlefinance(A9, ""low52""))"),50.71) -> 50.71 | M9: =IFERROR(__xludf.DUMMYFUNCTION("IF(ISBLANK(A9),"""",IFERROR(SPARKLINE((F9-L9)/(N9-L9),{""charttype"",""bar"";""max"",1;""min"",0;""color1"",""2c79b5""}),""n/a""))"),"") | N9: =IFERROR(__xludf.DUMMYFUNCTION("IF(ISBLANK(A9),"""", googlefinance(A9, ""high52""))"),67.94) -> 67.94 | O9: =if(isblank(A9),"",(F9-E9)*D9) -> 315.59018 | P9: =if(isblank(A9),"",O9+AE9) -> 439.59018 | Q9: =iferror(if(D9<0,0,O9/(E9*D9)),"") -> 0.18637862 | R9: =if(isblank(A9),"",P9/(E9*D9)) -> 0.2596095 | S9: Stocks | T9: Real Estate | U9: Value Stocks | V9: =if(isblank(A9),"",AB9/$AB$32) -> 0.049839907 | W9: =IFERROR(__xludf.DUMMYFUNCTION("IfError(IF(isblank(A9),"""",split(AK9, ""()"")))"),3.5) -> 3.5 | X9: =IFERROR(__xludf.DUMMYFUNCTION("""COMPUTED_VALUE"""),0.054) -> 0.054 | Y9: =IFERROR(W9/E9,"") -> 0.064079092 | Z9: 0.0355 | AA9: =iferror(if(isblank(A9),"",D9*E9),0) -> 1693.2746 | AB9: =IF(ISBLANK(A9),"",D9*F9) -> 2008.8648 | AC9: =IFERROR(IF(ISBLANK(A9),"",D9*W9),"") -> 108.5035 | AD9: =if(isblank(A9),"",AC9/$AC$32) -> 0.12293036 | AE9: =IF(ISBLANK($A9),"",SUM(OFFSET('Dividend Log'!$B$17, 0, ROW($A9)-2), OFFSET('Dividend Log'!$B$31, 0, ROW($A9)-2), OFFSET('Dividend Log'!$B$45, 0, ROW($A9)-2), OFFSET('Dividend Log'!$B$59, 0, ROW($A9)-2), OFFSET('Dividend Log'!$B$73, 0, ROW($A9)-2))) -> 124 | AF9: =IFERROR(AC9/F9,"") -> 1.6744367 | AG9: =iferror(IF(ISBLANK(G9),"",(F9-G9)/G9),"") -> 0.92742415 | AH9: =IF(AG9="", "", IF(AG9<=-15%, "Strong Buy", IF(AG9<0%, "Buy", IF(AG9<=15%, "Expensive", "Overrated")))) -> Overrated | AI9: =IF(ISBLANK(A9),"",(F9-E9)/E9) -> 0.18637862 | AJ9: =IF(A9="", "", IF(AI9<-15%, "Strong Buy", IF(AI9<-5%, "Buy", IF(AI9<5%, "Avg. Cost", IF(AI9<=15%, "Overcost", "Hold"))))) -> Hold | AK9: =IFERROR(__xludf.DUMMYFUNCTION("LET(t, A9, IF(t="""","""", IFERROR( SUBSTITUTE( INDEX( IMPORTXML( ""https://finviz.com/quote.ashx?t=""&t&""&ty=dv"", ""(//td[normalize-space()='Dividend TTM' or contains(.,'Dividend TTM')]/following-si"&"bling::td[1])[1]"" ),1,1), ""*"",""""), IFERROR( SUBSTITUTE( INDEX( IMPORTXML( ""https://finviz.com/quote.ashx?t=""&t, ""(//td[normalize-space()='Dividend']/following-sibling:"&":td[1])[1]"" ),1,1), ""*"",""""), """") ) ) ) "),"3.50 (5.40%)") -> 3.50 (5.40%)
A10: VICI | B10: =IFERROR(__xludf.DUMMYFUNCTION("IF(ISBLANK(A10),"""", googlefinance(A10, ""name""))"),"VICI Properties Inc") -> VICI Properties Inc | C10: =IF(ISBLANK(A10),"", HYPERLINK("https://seekingalpha.com/symbol/" & A10,"View")) -> View | D10: 15.874 | E10: 29.95 | F10: =IFERROR(__xludf.DUMMYFUNCTION("IF(ISBLANK(A10),"""", googlefinance(A10, ""price""))"),29.69) -> 29.69 | G10: =IF(ISBLANK(A10),"",IFERROR(VLOOKUP(A10, 'Intrinsic Values List'!$A$2:$D$70, 4, FALSE), "Not Found" )) -> 86.13 | H10: =IF(ISBLANK(A10),"",IFERROR(VLOOKUP(A10, 'Intrinsic Values List'!$A$2:$G$70, 7, FALSE), "Not Found" )) -> 5.78 | I10: =IFERROR(__xludf.DUMMYFUNCTION("IFERROR(googlefinance(A10,""change""),"""")"),-0.2) -> -0.2 | J10: =IFERROR(__xludf.DUMMYFUNCTION("iferror(GOOGLEFINANCE(A10,""changepct"")/100,"""")"),-0.0067) -> -0.0067 | K10: =if(isblank(A10),"",(D10*I10)) -> -3.1748 | L10: =IFERROR(__xludf.DUMMYFUNCTION("IF(ISBLANK(A10),"""", googlefinance(A10, ""low52""))"),27.48) -> 27.48 | M10: =IFERROR(__xludf.DUMMYFUNCTION("IF(ISBLANK(A10),"""",IFERROR(SPARKLINE((F10-L10)/(N10-L10),{""charttype"",""bar"";""max"",1;""min"",0;""color1"",""2c79b5""}),""n/a""))"),"") | N10: =IFERROR(__xludf.DUMMYFUNCTION("IF(ISBLANK(A10),"""", googlefinance(A10, ""high52""))"),34.03) -> 34.03 | O10: =if(isblank(A10),"",(F10-E10)*D10) -> -4.12724 | P10: =if(isblank(A10),"",O10+AE10) -> 22.89276 | Q10: =iferror(if(D10<0,0,O10/(E10*D10)),"") -> -0.0086811352 | R10: =if(isblank(A10),"",P10/(E10*D10)) -> 0.048152069 | S10: Stocks | T10: Real Estate | U10: Value Stocks | V10: =if(isblank(A10),"",AB10/$AB$32) -> 0.011692923 | W10: =IFERROR(__xludf.DUMMYFUNCTION("IfError(IF(isblank(A10),"""",split(AK10, ""()"")))"),1.76) -> 1.76 | X10: =IFERROR(__xludf.DUMMYFUNCTION("""COMPUTED_VALUE"""),0.0594) -> 0.0594 | Y10: =IFERROR(W10/E10,"") -> 0.058764608 | Z10: 0.0664 | AA10: =iferror(if(isblank(A10),"",D10*E10),0) -> 475.4263 | AB10: =IF(ISBLANK(A10),"",D10*F10) -> 471.29906 | AC10: =IFERROR(IF(ISBLANK(A10),"",D10*W10),"") -> 27.93824 | AD10: =if(isblank(A10),"",AC10/$AC$32) -> 0.031652969 | AE10: =IF(ISBLANK($A10),"",SUM(OFFSET('Dividend Log'!$B$17, 0, ROW($A10)-2), OFFSET('Dividend Log'!$B$31, 0, ROW($A10)-2), OFFSET('Dividend Log'!$B$45, 0, ROW($A10)-2), OFFSET('Dividend Log'!$B$59, 0, ROW($A10)-2), OFFSET('Dividend Log'!$B$73, 0, ROW($A10)-2))) -> 27.02 | AF10: =IFERROR(AC10/F10,"") -> 0.94099832 | AG10: =iferror(IF(ISBLANK(G10),"",(F10-G10)/G10),"") -> -0.65528852 | AH10: =IF(AG10="", "", IF(AG10<=-15%, "Strong Buy", IF(AG10<0%, "Buy", IF(AG10<=15%, "Expensive", "Overrated")))) -> Strong Buy | AI10: =IF(ISBLANK(A10),"",(F10-E10)/E10) -> -0.0086811352 | AJ10: =IF(A10="", "", IF(AI10<-15%, "Strong Buy", IF(AI10<-5%, "Buy", IF(AI10<5%, "Avg. Cost", IF(AI10<=15%, "Overcost", "Hold"))))) -> Avg. Cost | AK10: =IFERROR(__xludf.DUMMYFUNCTION("LET(t, A10, IF(t="""","""", IFERROR( SUBSTITUTE( INDEX( IMPORTXML( ""https://finviz.com/quote.ashx?t=""&t&""&ty=dv"", ""(//td[normalize-space()='Dividend TTM' or contains(.,'Dividend TTM')]/following-s"&"ibling::td[1])[1]"" ),1,1), ""*"",""""), IFERROR( SUBSTITUTE( INDEX( IMPORTXML( ""https://finviz.com/quote.ashx?t=""&t, ""(//td[normalize-space()='Dividend']/following-sibling"&"::td[1])[1]"" ),1,1), ""*"",""""), """") ) ) ) "),"1.76 (5.94%)") -> 1.76 (5.94%)
A11: UNH | B11: =IFERROR(__xludf.DUMMYFUNCTION("IF(ISBLANK(A11),"""", googlefinance(A11, ""name""))"),"UnitedHealth Group Inc") -> UnitedHealth Group Inc | C11: =IF(ISBLANK(A11),"", HYPERLINK("https://seekingalpha.com/symbol/" & A11,"View")) -> View | D11: 5.066 | E11: 261.98 | F11: =IFERROR(__xludf.DUMMYFUNCTION("IF(ISBLANK(A11),"""", googlefinance(A11, ""price""))"),288.77) -> 288.77 | G11: =IF(ISBLANK(A11),"",IFERROR(VLOOKUP(A11, 'Intrinsic Values List'!$A$2:$D$70, 4, FALSE), "Not Found" )) -> 362.68 | H11: =IF(ISBLANK(A11),"",IFERROR(VLOOKUP(A11, 'Intrinsic Values List'!$A$2:$G$70, 7, FALSE), "Not Found" )) -> 5 | I11: =IFERROR(__xludf.DUMMYFUNCTION("IFERROR(googlefinance(A11,""change""),"""")"),-3.19) -> -3.19 | J11: =IFERROR(__xludf.DUMMYFUNCTION("iferror(GOOGLEFINANCE(A11,""changepct"")/100,"""")"),-0.0109) -> -0.0109 | K11: =if(isblank(A11),"",(D11*I11)) -> -16.16054 | L11: =IFERROR(__xludf.DUMMYFUNCTION("IF(ISBLANK(A11),"""", googlefinance(A11, ""low52""))"),234.6) -> 234.6 | M11: =IFERROR(__xludf.DUMMYFUNCTION("IF(ISBLANK(A11),"""",IFERROR(SPARKLINE((F11-L11)/(N11-L11),{""charttype"",""bar"";""max"",1;""min"",0;""color1"",""2c79b5""}),""n/a""))"),"") | N11: =IFERROR(__xludf.DUMMYFUNCTION("IF(ISBLANK(A11),"""", googlefinance(A11, ""high52""))"),606.36) -> 606.36 | O11: =if(isblank(A11),"",(F11-E11)*D11) -> 135.71814 | P11: =if(isblank(A11),"",O11+AE11) -> 157.88814 | Q11: =iferror(if(D11<0,0,O11/(E11*D11)),"") -> 0.10225971 | R11: =if(isblank(A11),"",P11/(E11*D11)) -> 0.11896417 | S11: Stocks | T11: Health Care | U11: Value Stocks | V11: =if(isblank(A11),"",AB11/$AB$32) -> 0.036294747 | W11: =IFERROR(__xludf.DUMMYFUNCTION("IfError(IF(isblank(A11),"""",split(AK11, ""()"")))"),8.73) -> 8.73 | X11: =IFERROR(__xludf.DUMMYFUNCTION("""COMPUTED_VALUE"""),0.0302) -> 0.0302 | Y11: =IFERROR(W11/E11,"") -> 0.033323154 | Z11: 0.0875 | AA11: =iferror(if(isblank(A11),"",D11*E11),0) -> 1327.1907 | AB11: =IF(ISBLANK(A11),"",D11*F11) -> 1462.9088 | AC11: =IFERROR(IF(ISBLANK(A11),"",D11*W11),"") -> 44.22618 | AD11: =if(isblank(A11),"",AC11/$AC$32) -> 0.050106589 | AE11: =IF(ISBLANK($A11),"",SUM(OFFSET('Dividend Log'!$B$17, 0, ROW($A11)-2), OFFSET('Dividend Log'!$B$31, 0, ROW($A11)-2), OFFSET('Dividend Log'!$B$45, 0, ROW($A11)-2), OFFSET('Dividend Log'!$B$59, 0, ROW($A11)-2), OFFSET('Dividend Log'!$B$73, 0, ROW($A11)-2))) -> 22.17 | AF11: =IFERROR(AC11/F11,"") -> 0.15315365 | AG11: =iferror(IF(ISBLANK(G11),"",(F11-G11)/G11),"") -> -0.20378846 | AH11: =IF(AG11="", "", IF(AG11<=-15%, "Strong Buy", IF(AG11<0%, "Buy", IF(AG11<=15%, "Expensive", "Overrated")))) -> Strong Buy | AI11: =IF(ISBLANK(A11),"",(F11-E11)/E11) -> 0.10225971 | AJ11: =IF(A11="", "", IF(AI11<-15%, "Strong Buy", IF(AI11<-5%, "Buy", IF(AI11<5%, "Avg. Cost", IF(AI11<=15%, "Overcost", "Hold"))))) -> Overcost | AK11: =IFERROR(__xludf.DUMMYFUNCTION("LET(t, A11, IF(t="""","""", IFERROR( SUBSTITUTE( INDEX( IMPORTXML( ""https://finviz.com/quote.ashx?t=""&t&""&ty=dv"", ""(//td[normalize-space()='Dividend TTM' or contains(.,'Dividend TTM')]/following-s"&"ibling::td[1])[1]"" ),1,1), ""*"",""""), IFERROR( SUBSTITUTE( INDEX( IMPORTXML( ""https://finviz.com/quote.ashx?t=""&t, ""(//td[normalize-space()='Dividend']/following-sibling"&"::td[1])[1]"" ),1,1), ""*"",""""), """") ) ) ) "),"8.73 (3.02%)") -> 8.73 (3.02%)
A12: VGT | B12: =IFERROR(__xludf.DUMMYFUNCTION("IF(ISBLANK(A12),"""", googlefinance(A12, ""name""))"),"Vanguard Information Technology Index Fund ETF") -> Vanguard Information Technology Index Fund ETF | C12: =IF(ISBLANK(A12),"", HYPERLINK("https://seekingalpha.com/symbol/" & A12,"View")) -> View | D12: 3.015 | E12: 507.59 | F12: =IFERROR(__xludf.DUMMYFUNCTION("IF(ISBLANK(A12),"""", googlefinance(A12, ""price""))"),733.27) -> 733.27 | G12: =IF(ISBLANK(A12),"",IFERROR(VLOOKUP(A12, 'Intrinsic Values List'!$A$2:$D$70, 4, FALSE), "Not Found" )) -> Not Found | H12: =IF(ISBLANK(A12),"",IFERROR(VLOOKUP(A12, 'Intrinsic Values List'!$A$2:$G$70, 7, FALSE), "Not Found" )) -> Not Found | I12: =IFERROR(__xludf.DUMMYFUNCTION("IFERROR(googlefinance(A12,""change""),"""")"),0.14) -> 0.14 | J12: =IFERROR(__xludf.DUMMYFUNCTION("iferror(GOOGLEFINANCE(A12,""changepct"")/100,"""")"),2.0E-4) -> 0.0002 | K12: =if(isblank(A12),"",(D12*I12)) -> 0.4221 | L12: =IFERROR(__xludf.DUMMYFUNCTION("IF(ISBLANK(A12),"""", googlefinance(A12, ""low52""))"),451.0) -> 451 | M12: =IFERROR(__xludf.DUMMYFUNCTION("IF(ISBLANK(A12),"""",IFERROR(SPARKLINE((F12-L12)/(N12-L12),{""charttype"",""bar"";""max"",1;""min"",0;""color1"",""2c79b5""}),""n/a""))"),"") | N12: =IFERROR(__xludf.DUMMYFUNCTION("IF(ISBLANK(A12),"""", googlefinance(A12, ""high52""))"),806.99) -> 806.99 | O12: =if(isblank(A12),"",(F12-E12)*D12) -> 680.4252 | P12: =if(isblank(A12),"",O12+AE12) -> 690.5852 | Q12: =iferror(if(D12<0,0,O12/(E12*D12)),"") -> 0.44461081 | R12: =if(isblank(A12),"",P12/(E12*D12)) -> 0.45124967 | S12: ETFs | T12: ETF | U12: Growth | V12: =if(isblank(A12),"",AB12/$AB$32) -> 0.054850141 | W12: =IFERROR(__xludf.DUMMYFUNCTION("IfError(IF(isblank(A12),"""",split(AK12, ""()"")))"),3.05) -> 3.05 | X12: =IFERROR(__xludf.DUMMYFUNCTION("""COMPUTED_VALUE"""),0.0042) -> 0.0042 | Y12: =IFERROR(W12/E12,"") -> 0.0060087866 | Z12: 0.0875 | AA12: =iferror(if(isblank(A12),"",D12*E12),0) -> 1530.3838 | AB12: =IF(ISBLANK(A12),"",D12*F12) -> 2210.809 | AC12: =IFERROR(IF(ISBLANK(A12),"",D12*W12),"") -> 9.19575 | AD12: =if(isblank(A12),"",AC12/$AC$32) -> 0.010418437 | AE12: =IF(ISBLANK($A12),"",SUM(OFFSET('Dividend Log'!$B$17, 0, ROW($A12)-2), OFFSET('Dividend Log'!$B$31, 0, ROW($A12)-2), OFFSET('Dividend Log'!$B$45, 0, ROW($A12)-2), OFFSET('Dividend Log'!$B$59, 0, ROW($A12)-2), OFFSET('Dividend Log'!$B$73, 0, ROW($A12)-2))) -> 10.16 | AF12: =IFERROR(AC12/F12,"") -> 0.012540742 | AG12: =iferror(IF(ISBLANK(G12),"",(F12-G12)/G12),"") | AH12: =IF(AG12="", "", IF(AG12<=-15%, "Strong Buy", IF(AG12<0%, "Buy", IF(AG12<=15%, "Expensive", "Overrated")))) | AI12: =IF(ISBLANK(A12),"",(F12-E12)/E12) -> 0.44461081 | AJ12: =IF(A12="", "", IF(AI12<-15%, "Strong Buy", IF(AI12<-5%, "Buy", IF(AI12<5%, "Avg. Cost", IF(AI12<=15%, "Overcost", "Hold"))))) -> Hold | AK12: =IFERROR(__xludf.DUMMYFUNCTION("LET(t, A12, IF(t="""","""", IFERROR( SUBSTITUTE( INDEX( IMPORTXML( ""https://finviz.com/quote.ashx?t=""&t&""&ty=dv"", ""(//td[normalize-space()='Dividend TTM' or contains(.,'Dividend TTM')]/following-s"&"ibling::td[1])[1]"" ),1,1), ""*"",""""), IFERROR( SUBSTITUTE( INDEX( IMPORTXML( ""https://finviz.com/quote.ashx?t=""&t, ""(//td[normalize-space()='Dividend']/following-sibling"&"::td[1])[1]"" ),1,1), ""*"",""""), """") ) ) ) "),"3.05 (0.42%)") -> 3.05 (0.42%)
A13: VOO | B13: =IFERROR(__xludf.DUMMYFUNCTION("IF(ISBLANK(A13),"""", googlefinance(A13, ""name""))"),"Vanguard S&P 500 ETF") -> Vanguard S&P 500 ETF | C13: =IF(ISBLANK(A13),"", HYPERLINK("https://seekingalpha.com/symbol/" & A13,"View")) -> View | D13: 3.064 | E13: 480.16 | F13: =IFERROR(__xludf.DUMMYFUNCTION("IF(ISBLANK(A13),"""", googlefinance(A13, ""price""))"),626.81) -> 626.81 | G13: =IF(ISBLANK(A13),"",IFERROR(VLOOKUP(A13, 'Intrinsic Values List'!$A$2:$D$70, 4, FALSE), "Not Found" )) -> Not Found | H13: =IF(ISBLANK(A13),"",IFERROR(VLOOKUP(A13, 'Intrinsic Values List'!$A$2:$G$70, 7, FALSE), "Not Found" )) -> Not Found | I13: =IFERROR(__xludf.DUMMYFUNCTION("IFERROR(googlefinance(A13,""change""),"""")"),-3.37) -> -3.37 | J13: =IFERROR(__xludf.DUMMYFUNCTION("iferror(GOOGLEFINANCE(A13,""changepct"")/100,"""")"),-0.0053) -> -0.0053 | K13: =if(isblank(A13),"",(D13*I13)) -> -10.32568 | L13: =IFERROR(__xludf.DUMMYFUNCTION("IF(ISBLANK(A13),"""", googlefinance(A13, ""low52""))"),442.8) -> 442.8 | M13: =IFERROR(__xludf.DUMMYFUNCTION("IF(ISBLANK(A13),"""",IFERROR(SPARKLINE((F13-L13)/(N13-L13),{""charttype"",""bar"";""max"",1;""min"",0;""color1"",""2c79b5""}),""n/a""))"),"") | N13: =IFERROR(__xludf.DUMMYFUNCTION("IF(ISBLANK(A13),"""", googlefinance(A13, ""high52""))"),641.8) -> 641.8 | O13: =if(isblank(A13),"",(F13-E13)*D13) -> 449.3356 | P13: =if(isblank(A13),"",O13+AE13) -> 484.5656 | Q13: =iferror(if(D13<0,0,O13/(E13*D13)),"") -> 0.30541903 | R13: =if(isblank(A13),"",P13/(E13*D13)) -> 0.3293653 | S13: ETFs | T13: ETF | U13: Foundational | V13: =if(isblank(A13),"",AB13/$AB$32) -> 0.047648715 | W13: =IFERROR(__xludf.DUMMYFUNCTION("IfError(IF(isblank(A13),"""",split(AK13, ""()"")))"),7.07) -> 7.07 | X13: =IFERROR(__xludf.DUMMYFUNCTION("""COMPUTED_VALUE"""),0.0113) -> 0.0113 | Y13: =IFERROR(W13/E13,"") -> 0.014724259 | Z13: 0.0465 | AA13: =iferror(if(isblank(A13),"",D13*E13),0) -> 1471.2102 | AB13: =IF(ISBLANK(A13),"",D13*F13) -> 1920.5458 | AC13: =IFERROR(IF(ISBLANK(A13),"",D13*W13),"") -> 21.66248 | AD13: =if(isblank(A13),"",AC13/$AC$32) -> 0.02454277 | AE13: =IF(ISBLANK($A13),"",SUM(OFFSET('Dividend Log'!$B$17, 0, ROW($A13)-2), OFFSET('Dividend Log'!$B$31, 0, ROW($A13)-2), OFFSET('Dividend Log'!$B$45, 0, ROW($A13)-2), OFFSET('Dividend Log'!$B$59, 0, ROW($A13)-2), OFFSET('Dividend Log'!$B$73, 0, ROW($A13)-2))) -> 35.23 | AF13: =IFERROR(AC13/F13,"") -> 0.034559883 | AG13: =iferror(IF(ISBLANK(G13),"",(F13-G13)/G13),"") | AH13: =IF(AG13="", "", IF(AG13<=-15%, "Strong Buy", IF(AG13<0%, "Buy", IF(AG13<=15%, "Expensive", "Overrated")))) | AI13: =IF(ISBLANK(A13),"",(F13-E13)/E13) -> 0.30541903 | AJ13: =IF(A13="", "", IF(AI13<-15%, "Strong Buy", IF(AI13<-5%, "Buy", IF(AI13<5%, "Avg. Cost", IF(AI13<=15%, "Overcost", "Hold"))))) -> Hold | AK13: =IFERROR(__xludf.DUMMYFUNCTION("LET(t, A13, IF(t="""","""", IFERROR( SUBSTITUTE( INDEX( IMPORTXML( ""https://finviz.com/quote.ashx?t=""&t&""&ty=dv"", ""(//td[normalize-space()='Dividend TTM' or contains(.,'Dividend TTM')]/following-s"&"ibling::td[1])[1]"" ),1,1), ""*"",""""), IFERROR( SUBSTITUTE( INDEX( IMPORTXML( ""https://finviz.com/quote.ashx?t=""&t, ""(//td[normalize-space()='Dividend']/following-sibling"&"::td[1])[1]"" ),1,1), ""*"",""""), """") ) ) ) "),"7.07 (1.13%)") -> 7.07 (1.13%)
A14: VTI | B14: =IFERROR(__xludf.DUMMYFUNCTION("IF(ISBLANK(A14),"""", googlefinance(A14, ""name""))"),"Vanguard Total Stock Market Index Fund ETF") -> Vanguard Total Stock Market Index Fund ETF | C14: =IF(ISBLANK(A14),"", HYPERLINK("https://seekingalpha.com/symbol/" & A14,"View")) -> View | D14: 8.147 | E14: 260.86 | F14: =IFERROR(__xludf.DUMMYFUNCTION("IF(ISBLANK(A14),"""", googlefinance(A14, ""price""))"),336.0) -> 336 | G14: =IF(ISBLANK(A14),"",IFERROR(VLOOKUP(A14, 'Intrinsic Values List'!$A$2:$D$70, 4, FALSE), "Not Found" )) -> Not Found | H14: =IF(ISBLANK(A14),"",IFERROR(VLOOKUP(A14, 'Intrinsic Values List'!$A$2:$G$70, 7, FALSE), "Not Found" )) -> Not Found | I14: =IFERROR(__xludf.DUMMYFUNCTION("IFERROR(googlefinance(A14,""change""),"""")"),-2.19) -> -2.19 | J14: =IFERROR(__xludf.DUMMYFUNCTION("iferror(GOOGLEFINANCE(A14,""changepct"")/100,"""")"),-0.006500000000000001) -> -0.0065 | K14: =if(isblank(A14),"",(D14*I14)) -> -17.84193 | L14: =IFERROR(__xludf.DUMMYFUNCTION("IF(ISBLANK(A14),"""", googlefinance(A14, ""low52""))"),236.5) -> 236.5 | M14: =IFERROR(__xludf.DUMMYFUNCTION("IF(ISBLANK(A14),"""",IFERROR(SPARKLINE((F14-L14)/(N14-L14),{""charttype"",""bar"";""max"",1;""min"",0;""color1"",""2c79b5""}),""n/a""))"),"") | N14: =IFERROR(__xludf.DUMMYFUNCTION("IF(ISBLANK(A14),"""", googlefinance(A14, ""high52""))"),344.4) -> 344.4 | O14: =if(isblank(A14),"",(F14-E14)*D14) -> 612.16558 | P14: =if(isblank(A14),"",O14+AE14) -> 656.26558 | Q14: =iferror(if(D14<0,0,O14/(E14*D14)),"") -> 0.28804723 | R14: =if(isblank(A14),"",P14/(E14*D14)) -> 0.30879796 | S14: ETFs | T14: ETF | U14: Foundational | V14: =if(isblank(A14),"",AB14/$AB$32) -> 0.067914657 | W14: =IFERROR(__xludf.DUMMYFUNCTION("IfError(IF(isblank(A14),"""",split(AK14, ""()"")))"),3.76) -> 3.76 | X14: =IFERROR(__xludf.DUMMYFUNCTION("""COMPUTED_VALUE"""),0.0112) -> 0.0112 | Y14: =IFERROR(W14/E14,"") -> 0.014413862 | Z14: 0.0471 | AA14: =iferror(if(isblank(A14),"",D14*E14),0) -> 2125.2264 | AB14: =IF(ISBLANK(A14),"",D14*F14) -> 2737.392 | AC14: =IFERROR(IF(ISBLANK(A14),"",D14*W14),"") -> 30.63272 | AD14: =if(isblank(A14),"",AC14/$AC$32) -> 0.034705713 | AE14: =IF(ISBLANK($A14),"",SUM(OFFSET('Dividend Log'!$B$17, 0, ROW($A14)-2), OFFSET('Dividend Log'!$B$31, 0, ROW($A14)-2), OFFSET('Dividend Log'!$B$45, 0, ROW($A14)-2), OFFSET('Dividend Log'!$B$59, 0, ROW($A14)-2), OFFSET('Dividend Log'!$B$73, 0, ROW($A14)-2))) -> 44.1 | AF14: =IFERROR(AC14/F14,"") -> 0.09116881 | AG14: =iferror(IF(ISBLANK(G14),"",(F14-G14)/G14),"") | AH14: =IF(AG14="", "", IF(AG14<=-15%, "Strong Buy", IF(AG14<0%, "Buy", IF(AG14<=15%, "Expensive", "Overrated")))) | AI14: =IF(ISBLANK(A14),"",(F14-E14)/E14) -> 0.28804723 | AJ14: =IF(A14="", "", IF(AI14<-15%, "Strong Buy", IF(AI14<-5%, "Buy", IF(AI14<5%, "Avg. Cost", IF(AI14<=15%, "Overcost", "Hold"))))) -> Hold | AK14: =IFERROR(__xludf.DUMMYFUNCTION("LET(t, A14, IF(t="""","""", IFERROR( SUBSTITUTE( INDEX( IMPORTXML( ""https://finviz.com/quote.ashx?t=""&t&""&ty=dv"", ""(//td[normalize-space()='Dividend TTM' or contains(.,'Dividend TTM')]/following-s"&"ibling::td[1])[1]"" ),1,1), ""*"",""""), IFERROR( SUBSTITUTE( INDEX( IMPORTXML( ""https://finviz.com/quote.ashx?t=""&t, ""(//td[normalize-space()='Dividend']/following-sibling"&"::td[1])[1]"" ),1,1), ""*"",""""), """") ) ) ) "),"3.76 (1.12%)") -> 3.76 (1.12%)
A15: SCHD | B15: =IFERROR(__xludf.DUMMYFUNCTION("IF(ISBLANK(A15),"""", googlefinance(A15, ""name""))"),"Schwab US Dividend Equity ETF") -> Schwab US Dividend Equity ETF | C15: =IF(ISBLANK(A15),"", HYPERLINK("https://seekingalpha.com/symbol/" & A15,"View")) -> View | D15: 186.205 | E15: 26.98 | F15: =IFERROR(__xludf.DUMMYFUNCTION("IF(ISBLANK(A15),"""", googlefinance(A15, ""price""))"),31.26) -> 31.26 | G15: =IF(ISBLANK(A15),"",IFERROR(VLOOKUP(A15, 'Intrinsic Values List'!$A$2:$D$70, 4, FALSE), "Not Found" )) -> Not Found | H15: =IF(ISBLANK(A15),"",IFERROR(VLOOKUP(A15, 'Intrinsic Values List'!$A$2:$G$70, 7, FALSE), "Not Found" )) -> Not Found | I15: =IFERROR(__xludf.DUMMYFUNCTION("IFERROR(googlefinance(A15,""change""),"""")"),-0.28) -> -0.28 | J15: =IFERROR(__xludf.DUMMYFUNCTION("iferror(GOOGLEFINANCE(A15,""changepct"")/100,"""")"),-0.0089) -> -0.0089 | K15: =if(isblank(A15),"",(D15*I15)) -> -52.1374 | L15: =IFERROR(__xludf.DUMMYFUNCTION("IF(ISBLANK(A15),"""", googlefinance(A15, ""low52""))"),23.88) -> 23.88 | M15: =IFERROR(__xludf.DUMMYFUNCTION("IF(ISBLANK(A15),"""",IFERROR(SPARKLINE((F15-L15)/(N15-L15),{""charttype"",""bar"";""max"",1;""min"",0;""color1"",""2c79b5""}),""n/a""))"),"") | N15: =IFERROR(__xludf.DUMMYFUNCTION("IF(ISBLANK(A15),"""", googlefinance(A15, ""high52""))"),31.95) -> 31.95 | O15: =if(isblank(A15),"",(F15-E15)*D15) -> 796.9574 | P15: =if(isblank(A15),"",O15+AE15) -> 994.2974 | Q15: =iferror(if(D15<0,0,O15/(E15*D15)),"") -> 0.15863603 | R15: =if(isblank(A15),"",P15/(E15*D15)) -> 0.19791696 | S15: ETFs | T15: ETF | U15: Value Stocks | V15: =if(isblank(A15),"",AB15/$AB$32) -> 0.14441318 | W15: =IFERROR(__xludf.DUMMYFUNCTION("IfError(IF(isblank(A15),"""",split(AK15, ""()"")))"),1.05) -> 1.05 | X15: =IFERROR(__xludf.DUMMYFUNCTION("""COMPUTED_VALUE"""),0.0335) -> 0.0335 | Y15: =IFERROR(W15/E15,"") -> 0.038917717 | Z15: 0.118 | AA15: =iferror(if(isblank(A15),"",D15*E15),0) -> 5023.8109 | AB15: =IF(ISBLANK(A15),"",D15*F15) -> 5820.7683 | AC15: =IFERROR(IF(ISBLANK(A15),"",D15*W15),"") -> 195.51525 | AD15: =if(isblank(A15),"",AC15/$AC$32) -> 0.22151138 | AE15: =IF(ISBLANK($A15),"",SUM(OFFSET('Dividend Log'!$B$17, 0, ROW($A15)-2), OFFSET('Dividend Log'!$B$31, 0, ROW($A15)-2), OFFSET('Dividend Log'!$B$45, 0, ROW($A15)-2), OFFSET('Dividend Log'!$B$59, 0, ROW($A15)-2), OFFSET('Dividend Log'!$B$73, 0, ROW($A15)-2))) -> 197.34 | AF15: =IFERROR(AC15/F15,"") -> 6.2544866 | AG15: =iferror(IF(ISBLANK(G15),"",(F15-G15)/G15),"") | AH15: =IF(AG15="", "", IF(AG15<=-15%, "Strong Buy", IF(AG15<0%, "Buy", IF(AG15<=15%, "Expensive", "Overrated")))) | AI15: =IF(ISBLANK(A15),"",(F15-E15)/E15) -> 0.15863603 | AJ15: =IF(A15="", "", IF(AI15<-15%, "Strong Buy", IF(AI15<-5%, "Buy", IF(AI15<5%, "Avg. Cost", IF(AI15<=15%, "Overcost", "Hold"))))) -> Hold | AK15: =IFERROR(__xludf.DUMMYFUNCTION("LET(t, A15, IF(t="""","""", IFERROR( SUBSTITUTE( INDEX( IMPORTXML( ""https://finviz.com/quote.ashx?t=""&t&""&ty=dv"", ""(//td[normalize-space()='Dividend TTM' or contains(.,'Dividend TTM')]/following-s"&"ibling::td[1])[1]"" ),1,1), ""*"",""""), IFERROR( SUBSTITUTE( INDEX( IMPORTXML( ""https://finviz.com/quote.ashx?t=""&t, ""(//td[normalize-space()='Dividend']/following-sibling"&"::td[1])[1]"" ),1,1), ""*"",""""), """") ) ) ) "),"1.05 (3.35%)") -> 1.05 (3.35%)
A16: VIG | B16: =IFERROR(__xludf.DUMMYFUNCTION("IF(ISBLANK(A16),"""", googlefinance(A16, ""name""))"),"Vanguard Dividend Appreciation Index Fund ETF") -> Vanguard Dividend Appreciation Index Fund ETF | C16: =IF(ISBLANK(A16),"", HYPERLINK("https://seekingalpha.com/symbol/" & A16,"View")) -> View | D16: 1.03 | E16: 179.84 | F16: =IFERROR(__xludf.DUMMYFUNCTION("IF(ISBLANK(A16),"""", googlefinance(A16, ""price""))"),223.45) -> 223.45 | G16: =IF(ISBLANK(A16),"",IFERROR(VLOOKUP(A16, 'Intrinsic Values List'!$A$2:$D$70, 4, FALSE), "Not Found" )) -> Not Found | H16: =IF(ISBLANK(A16),"",IFERROR(VLOOKUP(A16, 'Intrinsic Values List'!$A$2:$G$70, 7, FALSE), "Not Found" )) -> Not Found | I16: =IFERROR(__xludf.DUMMYFUNCTION("IFERROR(googlefinance(A16,""change""),"""")"),-2.07) -> -2.07 | J16: =IFERROR(__xludf.DUMMYFUNCTION("iferror(GOOGLEFINANCE(A16,""changepct"")/100,"""")"),-0.0092) -> -0.0092 | K16: =if(isblank(A16),"",(D16*I16)) -> -2.1321 | L16: =IFERROR(__xludf.DUMMYFUNCTION("IF(ISBLANK(A16),"""", googlefinance(A16, ""low52""))"),169.32) -> 169.32 | M16: =IFERROR(__xludf.DUMMYFUNCTION("IF(ISBLANK(A16),"""",IFERROR(SPARKLINE((F16-L16)/(N16-L16),{""charttype"",""bar"";""max"",1;""min"",0;""color1"",""2c79b5""}),""n/a""))"),"") | N16: =IFERROR(__xludf.DUMMYFUNCTION("IF(ISBLANK(A16),"""", googlefinance(A16, ""high52""))"),230.5) -> 230.5 | O16: =if(isblank(A16),"",(F16-E16)*D16) -> 44.9183 | P16: =if(isblank(A16),"",O16+AE16) -> 51.1683 | Q16: =iferror(if(D16<0,0,O16/(E16*D16)),"") -> 0.24249333 | R16: =if(isblank(A16),"",P16/(E16*D16)) -> 0.27623421 | S16: ETFs | T16: ETF | U16: Value Stocks | V16: =if(isblank(A16),"",AB16/$AB$32) -> 0.0057101051 | W16: =IFERROR(__xludf.DUMMYFUNCTION("IfError(IF(isblank(A16),"""",split(AK16, ""()"")))"),3.56) -> 3.56 | X16: =IFERROR(__xludf.DUMMYFUNCTION("""COMPUTED_VALUE"""),0.0159) -> 0.0159 | Y16: =IFERROR(W16/E16,"") -> 0.019795374 | Z16: 0.0846 | AA16: =iferror(if(isblank(A16),"",D16*E16),0) -> 185.2352 | AB16: =IF(ISBLANK(A16),"",D16*F16) -> 230.1535 | AC16: =IFERROR(IF(ISBLANK(A16),"",D16*W16),"") -> 3.6668 | AD16: =if(isblank(A16),"",AC16/$AC$32) -> 0.0041543457 | AE16: =IF(ISBLANK($A16),"",SUM(OFFSET('Dividend Log'!$B$17, 0, ROW($A16)-2), OFFSET('Dividend Log'!$B$31, 0, ROW($A16)-2), OFFSET('Dividend Log'!$B$45, 0, ROW($A16)-2), OFFSET('Dividend Log'!$B$59, 0, ROW($A16)-2), OFFSET('Dividend Log'!$B$73, 0, ROW($A16)-2))) -> 6.25 | AF16: =IFERROR(AC16/F16,"") -> 0.016409935 | AG16: =iferror(IF(ISBLANK(G16),"",(F16-G16)/G16),"") | AH16: =IF(AG16="", "", IF(AG16<=-15%, "Strong Buy", IF(AG16<0%, "Buy", IF(AG16<=15%, "Expensive", "Overrated")))) | AI16: =IF(ISBLANK(A16),"",(F16-E16)/E16) -> 0.24249333 | AJ16: =IF(A16="", "", IF(AI16<-15%, "Strong Buy", IF(AI16<-5%, "Buy", IF(AI16<5%, "Avg. Cost", IF(AI16<=15%, "Overcost", "Hold"))))) -> Hold | AK16: =IFERROR(__xludf.DUMMYFUNCTION("LET(t, A16, IF(t="""","""", IFERROR( SUBSTITUTE( INDEX( IMPORTXML( ""https://finviz.com/quote.ashx?t=""&t&""&ty=dv"", ""(//td[normalize-space()='Dividend TTM' or contains(.,'Dividend TTM')]/following-s"&"ibling::td[1])[1]"" ),1,1), ""*"",""""), IFERROR( SUBSTITUTE( INDEX( IMPORTXML( ""https://finviz.com/quote.ashx?t=""&t, ""(//td[normalize-space()='Dividend']/following-sibling"&"::td[1])[1]"" ),1,1), ""*"",""""), """") ) ) ) "),"3.56 (1.59%)") -> 3.56 (1.59%)
